# async函数
## 1. 含义
ES2017 标准引入了 `async` 函数，使得异步操作变得更加方便。
`async` 函数是什么？一句话，它就是 `Generator` 函数的语法糖。
```js
const { readFile } = require("fs"),
      { resolve: resolvePath } = require("path");

const readFilePromise = filename => new Promise((resolve, reject) => {
  readFile(resolvePath(__dirname, filename), (err, data) => {
    if (err) return reject(err);
    resolve(data);
  })
});

const asyncReadFile = async () => {
  let f1 = await readFilePromise("./name.txt"),
      f2 = await readFilePromise("./age.txt");
  console.log(f1.toString());
  console.log(f2.toString());
}

asyncReadFile().then(data => console.log(data));
// Stella Yang
// 18
// undefined    asyncReadFile没有return返回值
```

一比较就会发现，async函数就是将 Generator 函数的星号（*）替换成async，将yield替换成await，仅此而已。

`async`函数对 `Generator` 函数的改进，体现在以下四点。

- （1）内置执行器。
  Generator 函数的执行必须靠执行器，所以才有了co模块，而async函数自带执行器。也就是说，async函数的执行，与普通函数一模一样，只要一行。
  ```js
  asyncReadFile();
  ```
  上面的代码调用了asyncReadFile函数，然后它就会自动执行，输出最后结果。这完全不像 Generator 函数，需要调用next方法，或者用co模块，才能真正执行，得到最后结果。

- （2）更好的语义。
  async和await，比起星号和yield，语义更清楚了。async表示函数里有异步操作，await表示紧跟在后面的表达式需要等待结果。

- （3）更广的适用性。
  co模块约定，yield命令后面只能是 Thunk 函数或 Promise 对象，而async函数的await命令后面，可以是 Promise 对象和原始类型的值（数值、字符串和布尔值，但这时会自动转成立即 resolved 的 Promise 对象）。

- （4）返回值是 Promise。
  async函数的返回值是 Promise 对象，这比 Generator 函数的返回值是 Iterator 对象方便多了。你可以用then方法指定下一步的操作。

> 进一步说，async函数完全可以看作多个异步操作，包装成的一个 Promise 对象，而await命令就是内部then命令的语法糖。


## 2. 基本用法
`async`函数返回一个 `Promise` 对象，可以使用`then`方法添加回调函数。当函数执行的时候，一旦遇到`awai`t`就会先返回，等到异步操作完成，再接着执行函数体内后面的语句。

```js
function timeout(ms) {
  return new Promise(resolve => {
    setTimeout(resolve, ms);
  })
}

async function asyncPrint(value, ms) {
  await timeout(ms);
  console.log(value);
}

asyncPrint("Bonjour!", 1000)
```

`async`函数的多种形式
```js
// 函数声明
async function foo() {}

// 函数表达式
const foo = async function() {}

// 对象方法
let obj = { async foo() {} };
obj.foo().then();

// Class方法
class Storage {
  constructor() {
    this.cachePromise = caches.open("avatars");
  }
  async getAvatar(name) {
    const cache = await this.cachePromise;
    return cache.match(`/avatars/${name}.png`);
  }
}
const storage = new Storage();
storage.getAvatar("jake").then(...);

// arrow function
const foo = async () => {};
```


## 3. 语法
In general, async grammar is simple, but its error hanling is not that easy.

### 3.1 返回Promise对象
async内部可以return value，也可以throw error，再链式操作的then/ catch进行相应的操作
```js
async function foo() {
  return "Yeah, I'm successful!"
}
foo().then(data => console.log(data));
// "Yeah, I'm successful!"

async function foo() {
  throw new Error("Oops, something gets wrong!");
}

foo().catch(err => console.log(err));
// Error: Oops, something gets wrong!
```

### 3.2 Promise 对象的状态变化
只有在`async`函数内部的`await`异步操作都执行完成后，Promise对象才会发生状体改变
除非遇到return语句或者抛出错误。
只有async函数内部的异步操作执行完，才会执行then方法指定的回调函数。
```js
const url = "htpp://someurl.com";
const fetch = url => new Promise(resolve => resolve({ text() {return "html"} }));

async function fetchUsers(url) {
  let response = await fetch(url),
      html = response.text();
  console.log(html);
  return html;
}

fetchUsers(url).then(console.log);
```

### 3.3 await 命令
正常情况下，`await`命令后面是一个 `Promise` 对象，返回该对象的结果。如果不是 `Promise` 对象，就直接返回对应的值。
```js
// 借助await让程序停顿指定的时间   进入休眠
function sleep(interval) {
  return new Promise(resolve => {
    setTimeout(resolve, interval);
  })
}

async function one2FiveInAsync() {
  for (let i = 0; i <= 5; i++) {
    console.log(i);
    await sleep(1000);
  }
}

one2FiveInAsync();
```

`await`命令后面的 `Promise` 对象如果变为 `reject`状态，则 `reject` 的参数会被 `catch` 方法的回调函数接收到。`
```js
// 任何一个await语句后面的 Promise 对象变为reject状态，那么整个async函数都会中断执行。

async function f() {
  await Promise.reject("出错了"); 
  await Promise.resolve("会执行吗?");  // 并不会
}
f().catch(data => console.log(data));

// 解决就算第一个await失败，也不影响后面的执行操作
// （1）
async function f() {
  try {
    await Promise.reject("出错了"); 
  } catch (error) {
    console.log(error);
  }
  return await Promise.resolve("会执行吗?");  
}

f().then(
  data => console.log(data),
  err => console.log(err),
)

// （2）
async function f() {
  await Promise.reject("出错了").catch(err => console.log(err)); 
  return await Promise.resolve("会执行吗?");  
}

f().then(
  data => console.log(data),
  err => console.log(err),
)
```

### 3.4 出错机制
```js
// 如果await后面的异步操作出错，那么等同于async函数返回的 Promise 对象被reject。

async function f() {
  await new Promise(function (resolve, reject) {
    throw new Error('出错了');
  });
}

f()
.then(v => console.log(v))
.catch(e => console.log(e))
// Error：出错了

// 防止出错的方法，也是将其放在try...catch代码块之中。
async function f() {
  try {
    await new Promise(function (resolve, reject) {
      throw new Error('出错了');
    });
  } catch(e) {
  }
  return await('hello world');
}
```

如果有多个 `await` 命令，可以统一放在 `try...catch` 结构中。
```js
async function main () {
  try {
    const v1 = await firstSetp();
    const v2 = await secondStep(v1);
    const v3 = await thirdStep(v2);

    console.log("Final: ", v3);
  } catch (error) {
    console.log(error);
  }
}
```

### 3.5 Note
```js
// 第一点，前面已经说过，await命令后面的Promise对象，运行结果可能是rejected，所以最好把await命令放在try...catch代码块中。

// 第二点，多个await命令后面的异步操作，如果不存在继发关系，最好让它们同时触发。
let foo = await getFoo();
let bar = await getBar();

// updated 1
let [ foo, bar ] = await Promise.all([getFoo(), getBar()]);

// updated2
let fooPromise = getFoo();
let barPromise = getBar();
let foo = await fooPromise();
let bar = await barPromise();
// 同时触发就会缩短时间

// 第三点，await命令只能用在async函数之中，如果用在普通函数，就会报错。

// 第四点，async 函数可以保留运行堆栈。
const a = () => {
  b().then(() => c());
}

// updated
const a = async () => {
  await b();
  c();
}
```

## 4. async 函数的实现原理


